# Java中的异常处理

[参考文档](https://baijiahao.baidu.com/s?id=1634759641294305924&wfr=spider&for=pc)



## Java中错误异常的组成

![](picture\17-1 Throwable.png)



## 非运行时异常，可查异常

这里主要分析 try - catch - finally 的实现原理和相关机制



### 1. 

try 正常结束，在 try 都执行后，再执行 finally 块

try 异常，去相应 catch 块执行后，再执行 finally 块

> 但是如果存在控制转移语句（return、break、continue、throw）呢？
>
> return、throw 把程序控制权交给它们的调用者（invoker）



### 2. finally 语句块在控制转移语句前执行

finally 语句块在控制转移语句前执行

原理：

JVM 将 finally 语句块作为 subroutine 插入到 try 语句块或 catch 语句块的控制转移语句前。

在执行 subroutine（finally 语句块）前，try 或 catch 语句块会从**操作数栈**中保留其**返回值**到本地变量表（Local Variable Table）。**待 subroutine 执行完后，再恢复保留的返回值到操作数栈中**，然后通过 return 或 throw 语句将其返回给该方法的调用者（invoker）。

（只适用于 return 和 throw，不适用于 break 和 continue）



### 3. 如果代码发生运行时异常

当出现异常，会产生一个 exception ，把它压入当前操作数栈的栈顶。然后把 exception 对象**从操作数栈保存到本地变量表**，然后执行 finally 语句块，待 finally 语句块执行完后，再把预先存储的 exception 对象**恢复到操作数栈**。最后由 athrow 指令将其返回给该方法的调用者（invoke）。



### 4. 例子：

```java
try {
    return test1();
} finally {
    System.out.print("finally语句块");
}

String test1() {
    System.out.print("");
}

try {
    String tmp = test1();
    return tmp;
} finally {
    System.out.print("finally语句块")
}
```

try 语句块里面是 `return test1()` ，但是编译后的执行逻辑是 `String tmp = test1(); return tmp;`  

所以，会先执行 `String tmp = test1();` ，再执行 finally 语句块，最后执行 `return tmp;` 。



### 5. finally是否一定执行？

官方文档《The Java Tutorials》：The finally Block

  The finally block always executes when the try block exits.

  Note: If the JVM exits while the try or catch code is being executed, then the finally block may not execute.

Likewise, if the thread executing the try or catch code is interrupted or killed, the finally block may not execute even though the application as a whole continues.



上述文档的意思是：

1. 当 try 块退出时，finally 块必定会执行。

   （但是如果还未进入 try 块，就返回或抛出异常，则 finally 块不会执行）

2. 当 try 或 catch 代码执行时，JVM 退出，finally 块不会执行。

   the thread is interrupted or killed（线程被打断或清除），finally 块不会执行，即使应用仍在进行。































